[2023-11-22T19:14:25.942+0000] {taskinstance.py:1159} INFO - Dependencies all met for dep_context=non-requeueable deps ti=<TaskInstance: COVID-19.Transform_data manual__2023-11-22T19:14:16.751258+00:00 [queued]>
[2023-11-22T19:14:25.958+0000] {taskinstance.py:1159} INFO - Dependencies all met for dep_context=requeueable deps ti=<TaskInstance: COVID-19.Transform_data manual__2023-11-22T19:14:16.751258+00:00 [queued]>
[2023-11-22T19:14:25.959+0000] {taskinstance.py:1361} INFO - Starting attempt 1 of 1
[2023-11-22T19:14:25.980+0000] {taskinstance.py:1382} INFO - Executing <Task(PythonOperator): Transform_data> on 2023-11-22 19:14:16.751258+00:00
[2023-11-22T19:14:25.987+0000] {standard_task_runner.py:57} INFO - Started process 279 to run task
[2023-11-22T19:14:25.991+0000] {standard_task_runner.py:84} INFO - Running: ['***', 'tasks', 'run', 'COVID-19', 'Transform_data', 'manual__2023-11-22T19:14:16.751258+00:00', '--job-id', '31', '--raw', '--subdir', 'DAGS_FOLDER/dag_etl.py', '--cfg-path', '/tmp/tmp3kn4x4wv']
[2023-11-22T19:14:25.994+0000] {standard_task_runner.py:85} INFO - Job 31: Subtask Transform_data
[2023-11-22T19:14:26.058+0000] {task_command.py:416} INFO - Running <TaskInstance: COVID-19.Transform_data manual__2023-11-22T19:14:16.751258+00:00 [running]> on host fa089f974649
[2023-11-22T19:14:26.339+0000] {taskinstance.py:1662} INFO - Exporting env vars: AIRFLOW_CTX_DAG_OWNER='***' AIRFLOW_CTX_DAG_ID='COVID-19' AIRFLOW_CTX_TASK_ID='Transform_data' AIRFLOW_CTX_EXECUTION_DATE='2023-11-22T19:14:16.751258+00:00' AIRFLOW_CTX_TRY_NUMBER='1' AIRFLOW_CTX_DAG_RUN_ID='manual__2023-11-22T19:14:16.751258+00:00'
[2023-11-22T19:14:26.807+0000] {taskinstance.py:1937} ERROR - Task failed with exception
Traceback (most recent call last):
  File "/home/airflow/.local/lib/python3.8/site-packages/airflow/operators/python.py", line 192, in execute
    return_value = self.execute_callable()
  File "/home/airflow/.local/lib/python3.8/site-packages/airflow/operators/python.py", line 209, in execute_callable
    return self.python_callable(*self.op_args, **self.op_kwargs)
  File "/opt/airflow/dags/dag_etl.py", line 43, in transform_data
    df.to_csv(os.path.expandvars("${AIRFLOW_HOME}/data/test.csv"), sep=";", index=False)
  File "/home/airflow/.local/lib/python3.8/site-packages/pandas/core/generic.py", line 3772, in to_csv
    return DataFrameRenderer(formatter).to_csv(
  File "/home/airflow/.local/lib/python3.8/site-packages/pandas/io/formats/format.py", line 1186, in to_csv
    csv_formatter.save()
  File "/home/airflow/.local/lib/python3.8/site-packages/pandas/io/formats/csvs.py", line 240, in save
    with get_handle(
  File "/home/airflow/.local/lib/python3.8/site-packages/pandas/io/common.py", line 859, in get_handle
    handle = open(
PermissionError: [Errno 13] Permission denied: '/opt/airflow/data/test.csv'
[2023-11-22T19:14:26.833+0000] {taskinstance.py:1400} INFO - Marking task as FAILED. dag_id=COVID-19, task_id=Transform_data, execution_date=20231122T191416, start_date=20231122T191425, end_date=20231122T191426
[2023-11-22T19:14:26.854+0000] {standard_task_runner.py:104} ERROR - Failed to execute job 31 for task Transform_data ([Errno 13] Permission denied: '/opt/airflow/data/test.csv'; 279)
[2023-11-22T19:14:26.888+0000] {local_task_job_runner.py:228} INFO - Task exited with return code 1
[2023-11-22T19:14:26.912+0000] {taskinstance.py:2778} INFO - 0 downstream tasks scheduled from follow-on schedule check
