[2023-11-23T23:06:53.453+0000] {taskinstance.py:1159} INFO - Dependencies all met for dep_context=non-requeueable deps ti=<TaskInstance: COVID-19.Data_transform_and_load manual__2023-11-23T22:53:17.833739+00:00 [queued]>
[2023-11-23T23:06:53.460+0000] {taskinstance.py:1159} INFO - Dependencies all met for dep_context=requeueable deps ti=<TaskInstance: COVID-19.Data_transform_and_load manual__2023-11-23T22:53:17.833739+00:00 [queued]>
[2023-11-23T23:06:53.461+0000] {taskinstance.py:1361} INFO - Starting attempt 5 of 5
[2023-11-23T23:06:53.470+0000] {taskinstance.py:1382} INFO - Executing <Task(PythonOperator): Data_transform_and_load> on 2023-11-23 22:53:17.833739+00:00
[2023-11-23T23:06:53.473+0000] {standard_task_runner.py:57} INFO - Started process 3117 to run task
[2023-11-23T23:06:53.475+0000] {standard_task_runner.py:84} INFO - Running: ['***', 'tasks', 'run', 'COVID-19', 'Data_transform_and_load', 'manual__2023-11-23T22:53:17.833739+00:00', '--job-id', '118', '--raw', '--subdir', 'DAGS_FOLDER/dag_etl.py', '--cfg-path', '/tmp/tmpyggqb7_l']
[2023-11-23T23:06:53.477+0000] {standard_task_runner.py:85} INFO - Job 118: Subtask Data_transform_and_load
[2023-11-23T23:06:53.506+0000] {task_command.py:416} INFO - Running <TaskInstance: COVID-19.Data_transform_and_load manual__2023-11-23T22:53:17.833739+00:00 [running]> on host 89d301135b3a
[2023-11-23T23:06:53.701+0000] {taskinstance.py:1662} INFO - Exporting env vars: AIRFLOW_CTX_DAG_OWNER='***' AIRFLOW_CTX_DAG_ID='COVID-19' AIRFLOW_CTX_TASK_ID='Data_transform_and_load' AIRFLOW_CTX_EXECUTION_DATE='2023-11-23T22:53:17.833739+00:00' AIRFLOW_CTX_TRY_NUMBER='5' AIRFLOW_CTX_DAG_RUN_ID='manual__2023-11-23T22:53:17.833739+00:00'
[2023-11-23T23:06:53.936+0000] {base.py:73} INFO - Using connection ID 'postgres_connexion' for task execution.
[2023-11-23T23:06:54.066+0000] {warnings.py:109} WARNING - /opt/***/dags/dag_etl.py:71: SettingWithCopyWarning: 
A value is trying to be set on a copy of a slice from a DataFrame.
Try using .loc[row_indexer,col_indexer] = value instead

See the caveats in the documentation: https://pandas.pydata.org/pandas-docs/stable/user_guide/indexing.html#returning-a-view-versus-a-copy
  df_passage['nbre_pass_corona'] = df_passage['nbre_pass_corona'].astype(int)

[2023-11-23T23:06:54.078+0000] {warnings.py:109} WARNING - /opt/***/dags/dag_etl.py:72: SettingWithCopyWarning: 
A value is trying to be set on a copy of a slice from a DataFrame.
Try using .loc[row_indexer,col_indexer] = value instead

See the caveats in the documentation: https://pandas.pydata.org/pandas-docs/stable/user_guide/indexing.html#returning-a-view-versus-a-copy
  df_passage['nbre_pass_tot'] = df_passage['nbre_pass_tot'].astype(int)

[2023-11-23T23:06:54.079+0000] {taskinstance.py:1937} ERROR - Task failed with exception
Traceback (most recent call last):
  File "/home/airflow/.local/lib/python3.8/site-packages/airflow/operators/python.py", line 192, in execute
    return_value = self.execute_callable()
  File "/home/airflow/.local/lib/python3.8/site-packages/airflow/operators/python.py", line 209, in execute_callable
    return self.python_callable(*self.op_args, **self.op_kwargs)
  File "/opt/airflow/dags/dag_etl.py", line 73, in data_transform_and_load
    df_passage['nbre_pass_corona_h'] = df_passage['nbre_pass_corona_h'].astype(int)
  File "/home/airflow/.local/lib/python3.8/site-packages/pandas/core/generic.py", line 6324, in astype
    new_data = self._mgr.astype(dtype=dtype, copy=copy, errors=errors)
  File "/home/airflow/.local/lib/python3.8/site-packages/pandas/core/internals/managers.py", line 451, in astype
    return self.apply(
  File "/home/airflow/.local/lib/python3.8/site-packages/pandas/core/internals/managers.py", line 352, in apply
    applied = getattr(b, f)(**kwargs)
  File "/home/airflow/.local/lib/python3.8/site-packages/pandas/core/internals/blocks.py", line 511, in astype
    new_values = astype_array_safe(values, dtype, copy=copy, errors=errors)
  File "/home/airflow/.local/lib/python3.8/site-packages/pandas/core/dtypes/astype.py", line 242, in astype_array_safe
    new_values = astype_array(values, dtype, copy=copy)
  File "/home/airflow/.local/lib/python3.8/site-packages/pandas/core/dtypes/astype.py", line 187, in astype_array
    values = _astype_nansafe(values, dtype, copy=copy)
  File "/home/airflow/.local/lib/python3.8/site-packages/pandas/core/dtypes/astype.py", line 138, in _astype_nansafe
    return arr.astype(dtype, copy=True)
ValueError: cannot convert float NaN to integer
[2023-11-23T23:06:54.092+0000] {taskinstance.py:1400} INFO - Marking task as FAILED. dag_id=COVID-19, task_id=Data_transform_and_load, execution_date=20231123T225317, start_date=20231123T230653, end_date=20231123T230654
[2023-11-23T23:06:54.101+0000] {standard_task_runner.py:104} ERROR - Failed to execute job 118 for task Data_transform_and_load (cannot convert float NaN to integer; 3117)
[2023-11-23T23:06:54.129+0000] {local_task_job_runner.py:228} INFO - Task exited with return code 1
[2023-11-23T23:06:54.142+0000] {taskinstance.py:2778} INFO - 0 downstream tasks scheduled from follow-on schedule check
