[2023-11-23T20:40:14.233+0000] {taskinstance.py:1159} INFO - Dependencies all met for dep_context=non-requeueable deps ti=<TaskInstance: COVID-19.Data_transform_and_load manual__2023-11-22T22:30:11.481856+00:00 [queued]>
[2023-11-23T20:40:14.240+0000] {taskinstance.py:1159} INFO - Dependencies all met for dep_context=requeueable deps ti=<TaskInstance: COVID-19.Data_transform_and_load manual__2023-11-22T22:30:11.481856+00:00 [queued]>
[2023-11-23T20:40:14.240+0000] {taskinstance.py:1361} INFO - Starting attempt 3 of 3
[2023-11-23T20:40:14.249+0000] {taskinstance.py:1382} INFO - Executing <Task(PythonOperator): Data_transform_and_load> on 2023-11-22 22:30:11.481856+00:00
[2023-11-23T20:40:14.253+0000] {standard_task_runner.py:57} INFO - Started process 745 to run task
[2023-11-23T20:40:14.255+0000] {standard_task_runner.py:84} INFO - Running: ['***', 'tasks', 'run', 'COVID-19', 'Data_transform_and_load', 'manual__2023-11-22T22:30:11.481856+00:00', '--job-id', '81', '--raw', '--subdir', 'DAGS_FOLDER/dag_etl.py', '--cfg-path', '/tmp/tmphuaprxul']
[2023-11-23T20:40:14.257+0000] {standard_task_runner.py:85} INFO - Job 81: Subtask Data_transform_and_load
[2023-11-23T20:40:14.287+0000] {task_command.py:416} INFO - Running <TaskInstance: COVID-19.Data_transform_and_load manual__2023-11-22T22:30:11.481856+00:00 [running]> on host 89d301135b3a
[2023-11-23T20:40:14.486+0000] {taskinstance.py:1662} INFO - Exporting env vars: AIRFLOW_CTX_DAG_OWNER='***' AIRFLOW_CTX_DAG_ID='COVID-19' AIRFLOW_CTX_TASK_ID='Data_transform_and_load' AIRFLOW_CTX_EXECUTION_DATE='2023-11-22T22:30:11.481856+00:00' AIRFLOW_CTX_TRY_NUMBER='3' AIRFLOW_CTX_DAG_RUN_ID='manual__2023-11-22T22:30:11.481856+00:00'
[2023-11-23T20:40:14.700+0000] {warnings.py:109} WARNING - /opt/***/dags/dag_etl.py:52: FutureWarning: section/key [core/sql_alchemy_conn] has been deprecated, you should use[database/sql_alchemy_conn] instead. Please update your `conf.get*` call to use the new name
  conn_uri = conf.get('core', 'sql_alchemy_conn')

[2023-11-23T20:40:14.701+0000] {taskinstance.py:1937} ERROR - Task failed with exception
Traceback (most recent call last):
  File "/home/airflow/.local/lib/python3.8/site-packages/airflow/operators/python.py", line 192, in execute
    return_value = self.execute_callable()
  File "/home/airflow/.local/lib/python3.8/site-packages/airflow/operators/python.py", line 209, in execute_callable
    return self.python_callable(*self.op_args, **self.op_kwargs)
  File "/opt/airflow/dags/dag_etl.py", line 59, in data_transform_and_load
    df_departements_region.to_sql('departement', con=engine, if_exists='replace', index=False, chunksize=1000, columns=["num_dep", "dep_name", "region_name"])
TypeError: to_sql() got an unexpected keyword argument 'columns'
[2023-11-23T20:40:14.707+0000] {taskinstance.py:1400} INFO - Marking task as FAILED. dag_id=COVID-19, task_id=Data_transform_and_load, execution_date=20231122T223011, start_date=20231123T204014, end_date=20231123T204014
[2023-11-23T20:40:14.714+0000] {standard_task_runner.py:104} ERROR - Failed to execute job 81 for task Data_transform_and_load (to_sql() got an unexpected keyword argument 'columns'; 745)
[2023-11-23T20:40:14.748+0000] {local_task_job_runner.py:228} INFO - Task exited with return code 1
[2023-11-23T20:40:14.761+0000] {taskinstance.py:2778} INFO - 0 downstream tasks scheduled from follow-on schedule check
