[2023-11-23T21:02:38.607+0000] {taskinstance.py:1159} INFO - Dependencies all met for dep_context=non-requeueable deps ti=<TaskInstance: COVID-19.Data_transform_and_load manual__2023-11-22T22:30:11.481856+00:00 [queued]>
[2023-11-23T21:02:38.613+0000] {taskinstance.py:1159} INFO - Dependencies all met for dep_context=requeueable deps ti=<TaskInstance: COVID-19.Data_transform_and_load manual__2023-11-22T22:30:11.481856+00:00 [queued]>
[2023-11-23T21:02:38.614+0000] {taskinstance.py:1361} INFO - Starting attempt 9 of 9
[2023-11-23T21:02:38.623+0000] {taskinstance.py:1382} INFO - Executing <Task(PythonOperator): Data_transform_and_load> on 2023-11-22 22:30:11.481856+00:00
[2023-11-23T21:02:38.628+0000] {standard_task_runner.py:57} INFO - Started process 1108 to run task
[2023-11-23T21:02:38.630+0000] {standard_task_runner.py:84} INFO - Running: ['***', 'tasks', 'run', 'COVID-19', 'Data_transform_and_load', 'manual__2023-11-22T22:30:11.481856+00:00', '--job-id', '87', '--raw', '--subdir', 'DAGS_FOLDER/dag_etl.py', '--cfg-path', '/tmp/tmp5g35bxf3']
[2023-11-23T21:02:38.632+0000] {standard_task_runner.py:85} INFO - Job 87: Subtask Data_transform_and_load
[2023-11-23T21:02:38.664+0000] {task_command.py:416} INFO - Running <TaskInstance: COVID-19.Data_transform_and_load manual__2023-11-22T22:30:11.481856+00:00 [running]> on host 89d301135b3a
[2023-11-23T21:02:38.862+0000] {taskinstance.py:1662} INFO - Exporting env vars: AIRFLOW_CTX_DAG_OWNER='***' AIRFLOW_CTX_DAG_ID='COVID-19' AIRFLOW_CTX_TASK_ID='Data_transform_and_load' AIRFLOW_CTX_EXECUTION_DATE='2023-11-22T22:30:11.481856+00:00' AIRFLOW_CTX_TRY_NUMBER='9' AIRFLOW_CTX_DAG_RUN_ID='manual__2023-11-22T22:30:11.481856+00:00'
[2023-11-23T21:02:39.381+0000] {taskinstance.py:1937} ERROR - Task failed with exception
Traceback (most recent call last):
  File "/home/airflow/.local/lib/python3.8/site-packages/pandas/core/indexes/base.py", line 3653, in get_loc
    return self._engine.get_loc(casted_key)
  File "pandas/_libs/index.pyx", line 147, in pandas._libs.index.IndexEngine.get_loc
  File "pandas/_libs/index.pyx", line 176, in pandas._libs.index.IndexEngine.get_loc
  File "pandas/_libs/hashtable_class_helper.pxi", line 7080, in pandas._libs.hashtable.PyObjectHashTable.get_item
  File "pandas/_libs/hashtable_class_helper.pxi", line 7088, in pandas._libs.hashtable.PyObjectHashTable.get_item
KeyError: 'num_departement'

The above exception was the direct cause of the following exception:

Traceback (most recent call last):
  File "/home/airflow/.local/lib/python3.8/site-packages/airflow/operators/python.py", line 192, in execute
    return_value = self.execute_callable()
  File "/home/airflow/.local/lib/python3.8/site-packages/airflow/operators/python.py", line 209, in execute_callable
    return self.python_callable(*self.op_args, **self.op_kwargs)
  File "/opt/airflow/dags/dag_etl.py", line 52, in data_transform_and_load
    df['num_departement'] = df['num_departement'].astype(int)
  File "/home/airflow/.local/lib/python3.8/site-packages/pandas/core/frame.py", line 3761, in __getitem__
    indexer = self.columns.get_loc(key)
  File "/home/airflow/.local/lib/python3.8/site-packages/pandas/core/indexes/base.py", line 3655, in get_loc
    raise KeyError(key) from err
KeyError: 'num_departement'
[2023-11-23T21:02:39.410+0000] {taskinstance.py:1400} INFO - Marking task as FAILED. dag_id=COVID-19, task_id=Data_transform_and_load, execution_date=20231122T223011, start_date=20231123T210238, end_date=20231123T210239
[2023-11-23T21:02:39.420+0000] {standard_task_runner.py:104} ERROR - Failed to execute job 87 for task Data_transform_and_load ('num_departement'; 1108)
[2023-11-23T21:02:39.445+0000] {local_task_job_runner.py:228} INFO - Task exited with return code 1
[2023-11-23T21:02:39.462+0000] {taskinstance.py:2778} INFO - 0 downstream tasks scheduled from follow-on schedule check
