[2023-11-22T19:28:40.129+0000] {taskinstance.py:1159} INFO - Dependencies all met for dep_context=non-requeueable deps ti=<TaskInstance: COVID-19.Transform_data manual__2023-11-22T19:28:30.212830+00:00 [queued]>
[2023-11-22T19:28:40.145+0000] {taskinstance.py:1159} INFO - Dependencies all met for dep_context=requeueable deps ti=<TaskInstance: COVID-19.Transform_data manual__2023-11-22T19:28:30.212830+00:00 [queued]>
[2023-11-22T19:28:40.146+0000] {taskinstance.py:1361} INFO - Starting attempt 1 of 1
[2023-11-22T19:28:40.166+0000] {taskinstance.py:1382} INFO - Executing <Task(PythonOperator): Transform_data> on 2023-11-22 19:28:30.212830+00:00
[2023-11-22T19:28:40.174+0000] {standard_task_runner.py:57} INFO - Started process 532 to run task
[2023-11-22T19:28:40.178+0000] {standard_task_runner.py:84} INFO - Running: ['***', 'tasks', 'run', 'COVID-19', 'Transform_data', 'manual__2023-11-22T19:28:30.212830+00:00', '--job-id', '39', '--raw', '--subdir', 'DAGS_FOLDER/dag_etl.py', '--cfg-path', '/tmp/tmpq2llqoab']
[2023-11-22T19:28:40.182+0000] {standard_task_runner.py:85} INFO - Job 39: Subtask Transform_data
[2023-11-22T19:28:40.247+0000] {task_command.py:416} INFO - Running <TaskInstance: COVID-19.Transform_data manual__2023-11-22T19:28:30.212830+00:00 [running]> on host fa089f974649
[2023-11-22T19:28:40.570+0000] {taskinstance.py:1662} INFO - Exporting env vars: AIRFLOW_CTX_DAG_OWNER='***' AIRFLOW_CTX_DAG_ID='COVID-19' AIRFLOW_CTX_TASK_ID='Transform_data' AIRFLOW_CTX_EXECUTION_DATE='2023-11-22T19:28:30.212830+00:00' AIRFLOW_CTX_TRY_NUMBER='1' AIRFLOW_CTX_DAG_RUN_ID='manual__2023-11-22T19:28:30.212830+00:00'
[2023-11-22T19:28:41.035+0000] {taskinstance.py:1937} ERROR - Task failed with exception
Traceback (most recent call last):
  File "/home/airflow/.local/lib/python3.8/site-packages/airflow/operators/python.py", line 192, in execute
    return_value = self.execute_callable()
  File "/home/airflow/.local/lib/python3.8/site-packages/airflow/operators/python.py", line 209, in execute_callable
    return self.python_callable(*self.op_args, **self.op_kwargs)
  File "/opt/airflow/dags/dag_etl.py", line 43, in transform_data
    df.to_csv(os.path.expandvars("${AIRFLOW_HOME}/data/test.csv"), sep=";", index=False)
  File "/home/airflow/.local/lib/python3.8/site-packages/pandas/core/generic.py", line 3772, in to_csv
    return DataFrameRenderer(formatter).to_csv(
  File "/home/airflow/.local/lib/python3.8/site-packages/pandas/io/formats/format.py", line 1186, in to_csv
    csv_formatter.save()
  File "/home/airflow/.local/lib/python3.8/site-packages/pandas/io/formats/csvs.py", line 240, in save
    with get_handle(
  File "/home/airflow/.local/lib/python3.8/site-packages/pandas/io/common.py", line 859, in get_handle
    handle = open(
PermissionError: [Errno 13] Permission denied: '/opt/airflow/data/test.csv'
[2023-11-22T19:28:41.055+0000] {taskinstance.py:1400} INFO - Marking task as FAILED. dag_id=COVID-19, task_id=Transform_data, execution_date=20231122T192830, start_date=20231122T192840, end_date=20231122T192841
[2023-11-22T19:28:41.074+0000] {standard_task_runner.py:104} ERROR - Failed to execute job 39 for task Transform_data ([Errno 13] Permission denied: '/opt/airflow/data/test.csv'; 532)
[2023-11-22T19:28:41.116+0000] {local_task_job_runner.py:228} INFO - Task exited with return code 1
[2023-11-22T19:28:41.142+0000] {taskinstance.py:2778} INFO - 0 downstream tasks scheduled from follow-on schedule check
