[2023-11-23T22:06:59.505+0000] {taskinstance.py:1159} INFO - Dependencies all met for dep_context=non-requeueable deps ti=<TaskInstance: COVID-19.Data_transform_and_load manual__2023-11-23T21:07:10.646516+00:00 [queued]>
[2023-11-23T22:06:59.513+0000] {taskinstance.py:1159} INFO - Dependencies all met for dep_context=requeueable deps ti=<TaskInstance: COVID-19.Data_transform_and_load manual__2023-11-23T21:07:10.646516+00:00 [queued]>
[2023-11-23T22:06:59.513+0000] {taskinstance.py:1361} INFO - Starting attempt 8 of 8
[2023-11-23T22:06:59.524+0000] {taskinstance.py:1382} INFO - Executing <Task(PythonOperator): Data_transform_and_load> on 2023-11-23 21:07:10.646516+00:00
[2023-11-23T22:06:59.528+0000] {standard_task_runner.py:57} INFO - Started process 2140 to run task
[2023-11-23T22:06:59.533+0000] {standard_task_runner.py:84} INFO - Running: ['***', 'tasks', 'run', 'COVID-19', 'Data_transform_and_load', 'manual__2023-11-23T21:07:10.646516+00:00', '--job-id', '100', '--raw', '--subdir', 'DAGS_FOLDER/dag_etl.py', '--cfg-path', '/tmp/tmpf10iz7k1']
[2023-11-23T22:06:59.535+0000] {standard_task_runner.py:85} INFO - Job 100: Subtask Data_transform_and_load
[2023-11-23T22:06:59.572+0000] {task_command.py:416} INFO - Running <TaskInstance: COVID-19.Data_transform_and_load manual__2023-11-23T21:07:10.646516+00:00 [running]> on host 89d301135b3a
[2023-11-23T22:06:59.800+0000] {taskinstance.py:1662} INFO - Exporting env vars: AIRFLOW_CTX_DAG_OWNER='***' AIRFLOW_CTX_DAG_ID='COVID-19' AIRFLOW_CTX_TASK_ID='Data_transform_and_load' AIRFLOW_CTX_EXECUTION_DATE='2023-11-23T21:07:10.646516+00:00' AIRFLOW_CTX_TRY_NUMBER='8' AIRFLOW_CTX_DAG_RUN_ID='manual__2023-11-23T21:07:10.646516+00:00'
[2023-11-23T22:07:00.101+0000] {base.py:73} INFO - Using connection ID 'postgres_connexion' for task execution.
[2023-11-23T22:07:00.112+0000] {taskinstance.py:1937} ERROR - Task failed with exception
Traceback (most recent call last):
  File "/home/airflow/.local/lib/python3.8/site-packages/airflow/operators/python.py", line 192, in execute
    return_value = self.execute_callable()
  File "/home/airflow/.local/lib/python3.8/site-packages/airflow/operators/python.py", line 209, in execute_callable
    return self.python_callable(*self.op_args, **self.op_kwargs)
  File "/opt/airflow/dags/dag_etl.py", line 75, in data_transform_and_load
    engine = create_engine(conn_uri)
  File "<string>", line 2, in create_engine
  File "/home/airflow/.local/lib/python3.8/site-packages/sqlalchemy/util/deprecations.py", line 375, in warned
    return fn(*args, **kwargs)
  File "/home/airflow/.local/lib/python3.8/site-packages/sqlalchemy/engine/create.py", line 518, in create_engine
    entrypoint = u._get_entrypoint()
  File "/home/airflow/.local/lib/python3.8/site-packages/sqlalchemy/engine/url.py", line 662, in _get_entrypoint
    cls = registry.load(name)
  File "/home/airflow/.local/lib/python3.8/site-packages/sqlalchemy/util/langhelpers.py", line 343, in load
    raise exc.NoSuchModuleError(
sqlalchemy.exc.NoSuchModuleError: Can't load plugin: sqlalchemy.dialects:postgres
[2023-11-23T22:07:00.124+0000] {taskinstance.py:1400} INFO - Marking task as FAILED. dag_id=COVID-19, task_id=Data_transform_and_load, execution_date=20231123T210710, start_date=20231123T220659, end_date=20231123T220700
[2023-11-23T22:07:00.133+0000] {standard_task_runner.py:104} ERROR - Failed to execute job 100 for task Data_transform_and_load (Can't load plugin: sqlalchemy.dialects:postgres; 2140)
[2023-11-23T22:07:00.185+0000] {local_task_job_runner.py:228} INFO - Task exited with return code 1
[2023-11-23T22:07:00.198+0000] {taskinstance.py:2778} INFO - 0 downstream tasks scheduled from follow-on schedule check
