[2023-11-23T22:20:43.992+0000] {taskinstance.py:1159} INFO - Dependencies all met for dep_context=non-requeueable deps ti=<TaskInstance: COVID-19.Data_transform_and_load manual__2023-11-23T21:07:10.646516+00:00 [queued]>
[2023-11-23T22:20:44.000+0000] {taskinstance.py:1159} INFO - Dependencies all met for dep_context=requeueable deps ti=<TaskInstance: COVID-19.Data_transform_and_load manual__2023-11-23T21:07:10.646516+00:00 [queued]>
[2023-11-23T22:20:44.000+0000] {taskinstance.py:1361} INFO - Starting attempt 12 of 12
[2023-11-23T22:20:44.010+0000] {taskinstance.py:1382} INFO - Executing <Task(PythonOperator): Data_transform_and_load> on 2023-11-23 21:07:10.646516+00:00
[2023-11-23T22:20:44.014+0000] {standard_task_runner.py:57} INFO - Started process 2361 to run task
[2023-11-23T22:20:44.015+0000] {standard_task_runner.py:84} INFO - Running: ['***', 'tasks', 'run', 'COVID-19', 'Data_transform_and_load', 'manual__2023-11-23T21:07:10.646516+00:00', '--job-id', '104', '--raw', '--subdir', 'DAGS_FOLDER/dag_etl.py', '--cfg-path', '/tmp/tmp550g_a43']
[2023-11-23T22:20:44.018+0000] {standard_task_runner.py:85} INFO - Job 104: Subtask Data_transform_and_load
[2023-11-23T22:20:44.051+0000] {task_command.py:416} INFO - Running <TaskInstance: COVID-19.Data_transform_and_load manual__2023-11-23T21:07:10.646516+00:00 [running]> on host 89d301135b3a
[2023-11-23T22:20:44.270+0000] {taskinstance.py:1662} INFO - Exporting env vars: AIRFLOW_CTX_DAG_OWNER='***' AIRFLOW_CTX_DAG_ID='COVID-19' AIRFLOW_CTX_TASK_ID='Data_transform_and_load' AIRFLOW_CTX_EXECUTION_DATE='2023-11-23T21:07:10.646516+00:00' AIRFLOW_CTX_TRY_NUMBER='12' AIRFLOW_CTX_DAG_RUN_ID='manual__2023-11-23T21:07:10.646516+00:00'
[2023-11-23T22:20:44.517+0000] {base.py:73} INFO - Using connection ID 'postgres_connexion' for task execution.
[2023-11-23T22:20:44.538+0000] {taskinstance.py:1937} ERROR - Task failed with exception
Traceback (most recent call last):
  File "/home/airflow/.local/lib/python3.8/site-packages/airflow/operators/python.py", line 192, in execute
    return_value = self.execute_callable()
  File "/home/airflow/.local/lib/python3.8/site-packages/airflow/operators/python.py", line 209, in execute_callable
    return self.python_callable(*self.op_args, **self.op_kwargs)
  File "/opt/airflow/dags/dag_etl.py", line 59, in data_transform_and_load
    cursor.execute("INSERT INTO departement (num_departement, nom_departement, nom_region) VALUES (%s, %s, %s)", (df_departements_region['num_departement'], df_departements_region['nom_departement'], df_departements_region['nom_region']))
psycopg2.ProgrammingError: can't adapt type 'Series'
[2023-11-23T22:20:44.546+0000] {taskinstance.py:1400} INFO - Marking task as FAILED. dag_id=COVID-19, task_id=Data_transform_and_load, execution_date=20231123T210710, start_date=20231123T222043, end_date=20231123T222044
[2023-11-23T22:20:44.555+0000] {standard_task_runner.py:104} ERROR - Failed to execute job 104 for task Data_transform_and_load (can't adapt type 'Series'; 2361)
[2023-11-23T22:20:44.590+0000] {local_task_job_runner.py:228} INFO - Task exited with return code 1
[2023-11-23T22:20:44.602+0000] {taskinstance.py:2778} INFO - 0 downstream tasks scheduled from follow-on schedule check
