[2023-11-24T19:36:55.430+0000] {taskinstance.py:1159} INFO - Dependencies all met for dep_context=non-requeueable deps ti=<TaskInstance: COVID-19.Data_transform_and_load manual__2023-11-22T19:29:07.263785+00:00 [queued]>
[2023-11-24T19:36:55.444+0000] {taskinstance.py:1159} INFO - Dependencies all met for dep_context=requeueable deps ti=<TaskInstance: COVID-19.Data_transform_and_load manual__2023-11-22T19:29:07.263785+00:00 [queued]>
[2023-11-24T19:36:55.445+0000] {taskinstance.py:1361} INFO - Starting attempt 14 of 14
[2023-11-24T19:36:55.463+0000] {taskinstance.py:1382} INFO - Executing <Task(PythonOperator): Data_transform_and_load> on 2023-11-22 19:29:07.263785+00:00
[2023-11-24T19:36:55.470+0000] {standard_task_runner.py:57} INFO - Started process 1949 to run task
[2023-11-24T19:36:55.477+0000] {standard_task_runner.py:84} INFO - Running: ['***', 'tasks', 'run', 'COVID-19', 'Data_transform_and_load', 'manual__2023-11-22T19:29:07.263785+00:00', '--job-id', '92', '--raw', '--subdir', 'DAGS_FOLDER/dag_etl.py', '--cfg-path', '/tmp/tmpda3j_luo']
[2023-11-24T19:36:55.483+0000] {standard_task_runner.py:85} INFO - Job 92: Subtask Data_transform_and_load
[2023-11-24T19:36:55.539+0000] {task_command.py:416} INFO - Running <TaskInstance: COVID-19.Data_transform_and_load manual__2023-11-22T19:29:07.263785+00:00 [running]> on host 3742b108fdc7
[2023-11-24T19:36:55.825+0000] {taskinstance.py:1662} INFO - Exporting env vars: AIRFLOW_CTX_DAG_OWNER='***' AIRFLOW_CTX_DAG_ID='COVID-19' AIRFLOW_CTX_TASK_ID='Data_transform_and_load' AIRFLOW_CTX_EXECUTION_DATE='2023-11-22T19:29:07.263785+00:00' AIRFLOW_CTX_TRY_NUMBER='14' AIRFLOW_CTX_DAG_RUN_ID='manual__2023-11-22T19:29:07.263785+00:00'
[2023-11-24T19:36:56.505+0000] {warnings.py:109} WARNING - /opt/***/dags/dag_etl.py:67: SettingWithCopyWarning: 
A value is trying to be set on a copy of a slice from a DataFrame.
Try using .loc[row_indexer,col_indexer] = value instead

See the caveats in the documentation: https://pandas.pydata.org/pandas-docs/stable/user_guide/indexing.html#returning-a-view-versus-a-copy
  df_passage['nbre_pass_corona'] = df_passage['nbre_pass_corona'].fillna(0).astype(int)

[2023-11-24T19:36:56.534+0000] {warnings.py:109} WARNING - /opt/***/dags/dag_etl.py:68: SettingWithCopyWarning: 
A value is trying to be set on a copy of a slice from a DataFrame.
Try using .loc[row_indexer,col_indexer] = value instead

See the caveats in the documentation: https://pandas.pydata.org/pandas-docs/stable/user_guide/indexing.html#returning-a-view-versus-a-copy
  df_passage['nbre_pass_tot'] = df_passage['nbre_pass_tot'].fillna(0).astype(int)

[2023-11-24T19:36:56.550+0000] {warnings.py:109} WARNING - /opt/***/dags/dag_etl.py:69: SettingWithCopyWarning: 
A value is trying to be set on a copy of a slice from a DataFrame.
Try using .loc[row_indexer,col_indexer] = value instead

See the caveats in the documentation: https://pandas.pydata.org/pandas-docs/stable/user_guide/indexing.html#returning-a-view-versus-a-copy
  df_passage['nbre_pass_corona_h'] = df_passage['nbre_pass_corona_h'].fillna(0).astype(int)

[2023-11-24T19:36:56.565+0000] {warnings.py:109} WARNING - /opt/***/dags/dag_etl.py:70: SettingWithCopyWarning: 
A value is trying to be set on a copy of a slice from a DataFrame.
Try using .loc[row_indexer,col_indexer] = value instead

See the caveats in the documentation: https://pandas.pydata.org/pandas-docs/stable/user_guide/indexing.html#returning-a-view-versus-a-copy
  df_passage['nbre_pass_corona_f'] = df_passage['nbre_pass_corona_f'].fillna(0).astype(int)

[2023-11-24T19:36:56.582+0000] {warnings.py:109} WARNING - /opt/***/dags/dag_etl.py:71: SettingWithCopyWarning: 
A value is trying to be set on a copy of a slice from a DataFrame.
Try using .loc[row_indexer,col_indexer] = value instead

See the caveats in the documentation: https://pandas.pydata.org/pandas-docs/stable/user_guide/indexing.html#returning-a-view-versus-a-copy
  df_passage['nbre_pass_tot_h'] = df_passage['nbre_pass_tot_h'].fillna(0).astype(int)

[2023-11-24T19:36:56.602+0000] {warnings.py:109} WARNING - /opt/***/dags/dag_etl.py:72: SettingWithCopyWarning: 
A value is trying to be set on a copy of a slice from a DataFrame.
Try using .loc[row_indexer,col_indexer] = value instead

See the caveats in the documentation: https://pandas.pydata.org/pandas-docs/stable/user_guide/indexing.html#returning-a-view-versus-a-copy
  df_passage['nbre_pass_tot_f'] = df_passage['nbre_pass_tot_f'].fillna(0).astype(int)

[2023-11-24T19:36:56.635+0000] {warnings.py:109} WARNING - /opt/***/dags/dag_etl.py:79: SettingWithCopyWarning: 
A value is trying to be set on a copy of a slice from a DataFrame.
Try using .loc[row_indexer,col_indexer] = value instead

See the caveats in the documentation: https://pandas.pydata.org/pandas-docs/stable/user_guide/indexing.html#returning-a-view-versus-a-copy
  df_hospit['nbre_hospit_corona'] = df_hospit['nbre_hospit_corona'].fillna(0).astype(int)

[2023-11-24T19:36:56.650+0000] {warnings.py:109} WARNING - /opt/***/dags/dag_etl.py:80: SettingWithCopyWarning: 
A value is trying to be set on a copy of a slice from a DataFrame.
Try using .loc[row_indexer,col_indexer] = value instead

See the caveats in the documentation: https://pandas.pydata.org/pandas-docs/stable/user_guide/indexing.html#returning-a-view-versus-a-copy
  df_hospit['nbre_hospit_corona_h'] = df_hospit['nbre_hospit_corona_h'].fillna(0).astype(int)

[2023-11-24T19:36:56.667+0000] {warnings.py:109} WARNING - /opt/***/dags/dag_etl.py:81: SettingWithCopyWarning: 
A value is trying to be set on a copy of a slice from a DataFrame.
Try using .loc[row_indexer,col_indexer] = value instead

See the caveats in the documentation: https://pandas.pydata.org/pandas-docs/stable/user_guide/indexing.html#returning-a-view-versus-a-copy
  df_hospit['nbre_hospit_corona_f'] = df_hospit['nbre_hospit_corona_f'].fillna(0).astype(int)

[2023-11-24T19:36:56.681+0000] {base.py:73} INFO - Using connection ID 'postgres_connexion' for task execution.
[2023-11-24T19:36:57.114+0000] {taskinstance.py:1937} ERROR - Task failed with exception
Traceback (most recent call last):
  File "/home/airflow/.local/lib/python3.8/site-packages/airflow/operators/python.py", line 192, in execute
    return_value = self.execute_callable()
  File "/home/airflow/.local/lib/python3.8/site-packages/airflow/operators/python.py", line 209, in execute_callable
    return self.python_callable(*self.op_args, **self.op_kwargs)
  File "/opt/airflow/dags/dag_etl.py", line 107, in data_transform_and_load
    id_passage = cursor.fetchone()[0]
psycopg2.ProgrammingError: no results to fetch
[2023-11-24T19:36:57.140+0000] {taskinstance.py:1400} INFO - Marking task as FAILED. dag_id=COVID-19, task_id=Data_transform_and_load, execution_date=20231122T192907, start_date=20231124T193655, end_date=20231124T193657
[2023-11-24T19:36:57.161+0000] {standard_task_runner.py:104} ERROR - Failed to execute job 92 for task Data_transform_and_load (no results to fetch; 1949)
[2023-11-24T19:36:57.178+0000] {local_task_job_runner.py:228} INFO - Task exited with return code 1
[2023-11-24T19:36:57.202+0000] {taskinstance.py:2778} INFO - 0 downstream tasks scheduled from follow-on schedule check
