[2023-11-24T18:34:27.807+0000] {taskinstance.py:1159} INFO - Dependencies all met for dep_context=non-requeueable deps ti=<TaskInstance: COVID-19.Data_transform_and_load manual__2023-11-22T19:29:07.263785+00:00 [queued]>
[2023-11-24T18:34:27.823+0000] {taskinstance.py:1159} INFO - Dependencies all met for dep_context=requeueable deps ti=<TaskInstance: COVID-19.Data_transform_and_load manual__2023-11-22T19:29:07.263785+00:00 [queued]>
[2023-11-24T18:34:27.825+0000] {taskinstance.py:1361} INFO - Starting attempt 9 of 9
[2023-11-24T18:34:27.840+0000] {taskinstance.py:1382} INFO - Executing <Task(PythonOperator): Data_transform_and_load> on 2023-11-22 19:29:07.263785+00:00
[2023-11-24T18:34:27.847+0000] {standard_task_runner.py:57} INFO - Started process 982 to run task
[2023-11-24T18:34:27.850+0000] {standard_task_runner.py:84} INFO - Running: ['***', 'tasks', 'run', 'COVID-19', 'Data_transform_and_load', 'manual__2023-11-22T19:29:07.263785+00:00', '--job-id', '85', '--raw', '--subdir', 'DAGS_FOLDER/dag_etl.py', '--cfg-path', '/tmp/tmpc5i6hkm9']
[2023-11-24T18:34:27.853+0000] {standard_task_runner.py:85} INFO - Job 85: Subtask Data_transform_and_load
[2023-11-24T18:34:27.910+0000] {task_command.py:416} INFO - Running <TaskInstance: COVID-19.Data_transform_and_load manual__2023-11-22T19:29:07.263785+00:00 [running]> on host 3742b108fdc7
[2023-11-24T18:34:28.520+0000] {taskinstance.py:1662} INFO - Exporting env vars: AIRFLOW_CTX_DAG_OWNER='***' AIRFLOW_CTX_DAG_ID='COVID-19' AIRFLOW_CTX_TASK_ID='Data_transform_and_load' AIRFLOW_CTX_EXECUTION_DATE='2023-11-22T19:29:07.263785+00:00' AIRFLOW_CTX_TRY_NUMBER='9' AIRFLOW_CTX_DAG_RUN_ID='manual__2023-11-22T19:29:07.263785+00:00'
[2023-11-24T18:34:28.899+0000] {base.py:73} INFO - Using connection ID 'postgres_connexion' for task execution.
[2023-11-24T18:34:29.260+0000] {warnings.py:109} WARNING - /opt/***/dags/dag_etl.py:97: SettingWithCopyWarning: 
A value is trying to be set on a copy of a slice from a DataFrame.
Try using .loc[row_indexer,col_indexer] = value instead

See the caveats in the documentation: https://pandas.pydata.org/pandas-docs/stable/user_guide/indexing.html#returning-a-view-versus-a-copy
  df_hospit['nbre_hospit_corona'] = df_hospit['nbre_hospit_corona'].fillna(0).astype(int)

[2023-11-24T18:34:29.277+0000] {warnings.py:109} WARNING - /opt/***/dags/dag_etl.py:98: SettingWithCopyWarning: 
A value is trying to be set on a copy of a slice from a DataFrame.
Try using .loc[row_indexer,col_indexer] = value instead

See the caveats in the documentation: https://pandas.pydata.org/pandas-docs/stable/user_guide/indexing.html#returning-a-view-versus-a-copy
  df_hospit['nbre_hospit_corona_h'] = df_hospit['nbre_hospit_corona_h'].fillna(0).astype(int)

[2023-11-24T18:34:29.297+0000] {warnings.py:109} WARNING - /opt/***/dags/dag_etl.py:99: SettingWithCopyWarning: 
A value is trying to be set on a copy of a slice from a DataFrame.
Try using .loc[row_indexer,col_indexer] = value instead

See the caveats in the documentation: https://pandas.pydata.org/pandas-docs/stable/user_guide/indexing.html#returning-a-view-versus-a-copy
  df_hospit['nbre_hospit_corona_f'] = df_hospit['nbre_hospit_corona_f'].fillna(0).astype(int)

[2023-11-24T18:34:29.301+0000] {logging_mixin.py:151} INFO - nbre_hospit_corona      int64
nbre_hospit_corona_h    int64
nbre_hospit_corona_f    int64
dtype: object
[2023-11-24T18:34:29.308+0000] {base.py:73} INFO - Using connection ID 'postgres_connexion' for task execution.
[2023-11-24T18:34:29.325+0000] {taskinstance.py:1937} ERROR - Task failed with exception
Traceback (most recent call last):
  File "/home/airflow/.local/lib/python3.8/site-packages/airflow/operators/python.py", line 192, in execute
    return_value = self.execute_callable()
  File "/home/airflow/.local/lib/python3.8/site-packages/airflow/operators/python.py", line 209, in execute_callable
    return self.python_callable(*self.op_args, **self.op_kwargs)
  File "/opt/airflow/dags/dag_etl.py", line 107, in data_transform_and_load
    for _, row in df_passage.iterrows():
NameError: name 'df_passage' is not defined
[2023-11-24T18:34:29.340+0000] {taskinstance.py:1400} INFO - Marking task as FAILED. dag_id=COVID-19, task_id=Data_transform_and_load, execution_date=20231122T192907, start_date=20231124T183427, end_date=20231124T183429
[2023-11-24T18:34:29.361+0000] {standard_task_runner.py:104} ERROR - Failed to execute job 85 for task Data_transform_and_load (name 'df_passage' is not defined; 982)
[2023-11-24T18:34:29.391+0000] {local_task_job_runner.py:228} INFO - Task exited with return code 1
[2023-11-24T18:34:29.412+0000] {taskinstance.py:2778} INFO - 0 downstream tasks scheduled from follow-on schedule check
