[2023-11-22T21:33:05.278+0000] {taskinstance.py:1159} INFO - Dependencies all met for dep_context=non-requeueable deps ti=<TaskInstance: COVID-19.insert_data manual__2023-11-22T19:29:07.263785+00:00 [queued]>
[2023-11-22T21:33:05.292+0000] {taskinstance.py:1159} INFO - Dependencies all met for dep_context=requeueable deps ti=<TaskInstance: COVID-19.insert_data manual__2023-11-22T19:29:07.263785+00:00 [queued]>
[2023-11-22T21:33:05.293+0000] {taskinstance.py:1361} INFO - Starting attempt 1 of 1
[2023-11-22T21:33:05.312+0000] {taskinstance.py:1382} INFO - Executing <Task(PythonOperator): insert_data> on 2023-11-22 19:29:07.263785+00:00
[2023-11-22T21:33:05.321+0000] {standard_task_runner.py:57} INFO - Started process 636 to run task
[2023-11-22T21:33:05.323+0000] {standard_task_runner.py:84} INFO - Running: ['***', 'tasks', 'run', 'COVID-19', 'insert_data', 'manual__2023-11-22T19:29:07.263785+00:00', '--job-id', '53', '--raw', '--subdir', 'DAGS_FOLDER/dag_etl.py', '--cfg-path', '/tmp/tmpxlrzqvho']
[2023-11-22T21:33:05.327+0000] {standard_task_runner.py:85} INFO - Job 53: Subtask insert_data
[2023-11-22T21:33:05.387+0000] {task_command.py:416} INFO - Running <TaskInstance: COVID-19.insert_data manual__2023-11-22T19:29:07.263785+00:00 [running]> on host 6c2240d4b080
[2023-11-22T21:33:05.771+0000] {taskinstance.py:1662} INFO - Exporting env vars: AIRFLOW_CTX_DAG_OWNER='***' AIRFLOW_CTX_DAG_ID='COVID-19' AIRFLOW_CTX_TASK_ID='insert_data' AIRFLOW_CTX_EXECUTION_DATE='2023-11-22T19:29:07.263785+00:00' AIRFLOW_CTX_TRY_NUMBER='1' AIRFLOW_CTX_DAG_RUN_ID='manual__2023-11-22T19:29:07.263785+00:00'
[2023-11-22T21:33:13.780+0000] {taskinstance.py:1937} ERROR - Task failed with exception
Traceback (most recent call last):
  File "/home/airflow/.local/lib/python3.8/site-packages/airflow/operators/python.py", line 192, in execute
    return_value = self.execute_callable()
  File "/home/airflow/.local/lib/python3.8/site-packages/airflow/operators/python.py", line 209, in execute_callable
    return self.python_callable(*self.op_args, **self.op_kwargs)
  File "/opt/airflow/dags/dag_etl.py", line 49, in insert_data_into_db
    conn = psycopg2.connect(host="hostname", dbname="dbname", user="username", password="password")
  File "/home/airflow/.local/lib/python3.8/site-packages/psycopg2/__init__.py", line 122, in connect
    conn = _connect(dsn, connection_factory=connection_factory, **kwasync)
psycopg2.OperationalError: could not translate host name "hostname" to address: Temporary failure in name resolution

[2023-11-22T21:33:13.799+0000] {taskinstance.py:1400} INFO - Marking task as FAILED. dag_id=COVID-19, task_id=insert_data, execution_date=20231122T192907, start_date=20231122T213305, end_date=20231122T213313
[2023-11-22T21:33:13.818+0000] {standard_task_runner.py:104} ERROR - Failed to execute job 53 for task insert_data (could not translate host name "hostname" to address: Temporary failure in name resolution
; 636)
[2023-11-22T21:33:13.865+0000] {local_task_job_runner.py:228} INFO - Task exited with return code 1
[2023-11-22T21:33:13.889+0000] {taskinstance.py:2778} INFO - 0 downstream tasks scheduled from follow-on schedule check
