[2023-11-22T21:48:29.149+0000] {taskinstance.py:1159} INFO - Dependencies all met for dep_context=non-requeueable deps ti=<TaskInstance: COVID-19.insert_data manual__2023-11-22T19:29:07.263785+00:00 [queued]>
[2023-11-22T21:48:29.162+0000] {taskinstance.py:1159} INFO - Dependencies all met for dep_context=requeueable deps ti=<TaskInstance: COVID-19.insert_data manual__2023-11-22T19:29:07.263785+00:00 [queued]>
[2023-11-22T21:48:29.163+0000] {taskinstance.py:1361} INFO - Starting attempt 2 of 2
[2023-11-22T21:48:29.184+0000] {taskinstance.py:1382} INFO - Executing <Task(PythonOperator): insert_data> on 2023-11-22 19:29:07.263785+00:00
[2023-11-22T21:48:29.191+0000] {standard_task_runner.py:57} INFO - Started process 878 to run task
[2023-11-22T21:48:29.194+0000] {standard_task_runner.py:84} INFO - Running: ['***', 'tasks', 'run', 'COVID-19', 'insert_data', 'manual__2023-11-22T19:29:07.263785+00:00', '--job-id', '57', '--raw', '--subdir', 'DAGS_FOLDER/dag_etl.py', '--cfg-path', '/tmp/tmpl5lxaa7w']
[2023-11-22T21:48:29.196+0000] {standard_task_runner.py:85} INFO - Job 57: Subtask insert_data
[2023-11-22T21:48:29.259+0000] {task_command.py:416} INFO - Running <TaskInstance: COVID-19.insert_data manual__2023-11-22T19:29:07.263785+00:00 [running]> on host 6c2240d4b080
[2023-11-22T21:48:29.539+0000] {taskinstance.py:1662} INFO - Exporting env vars: AIRFLOW_CTX_DAG_OWNER='***' AIRFLOW_CTX_DAG_ID='COVID-19' AIRFLOW_CTX_TASK_ID='insert_data' AIRFLOW_CTX_EXECUTION_DATE='2023-11-22T19:29:07.263785+00:00' AIRFLOW_CTX_TRY_NUMBER='2' AIRFLOW_CTX_DAG_RUN_ID='manual__2023-11-22T19:29:07.263785+00:00'
[2023-11-22T21:48:29.543+0000] {taskinstance.py:1937} ERROR - Task failed with exception
Traceback (most recent call last):
  File "/home/airflow/.local/lib/python3.8/site-packages/airflow/operators/python.py", line 192, in execute
    return_value = self.execute_callable()
  File "/home/airflow/.local/lib/python3.8/site-packages/airflow/operators/python.py", line 209, in execute_callable
    return self.python_callable(*self.op_args, **self.op_kwargs)
  File "/opt/airflow/dags/dag_etl.py", line 49, in insert_data_into_db
    pg_hook = PostgresHook(postgres_conn_id='postgres_connexion')
NameError: name 'PostgresHook' is not defined
[2023-11-22T21:48:29.560+0000] {taskinstance.py:1400} INFO - Marking task as FAILED. dag_id=COVID-19, task_id=insert_data, execution_date=20231122T192907, start_date=20231122T214829, end_date=20231122T214829
[2023-11-22T21:48:29.577+0000] {standard_task_runner.py:104} ERROR - Failed to execute job 57 for task insert_data (name 'PostgresHook' is not defined; 878)
[2023-11-22T21:48:29.609+0000] {local_task_job_runner.py:228} INFO - Task exited with return code 1
[2023-11-22T21:48:29.633+0000] {taskinstance.py:2778} INFO - 0 downstream tasks scheduled from follow-on schedule check
