[2023-11-22T21:49:50.033+0000] {taskinstance.py:1159} INFO - Dependencies all met for dep_context=non-requeueable deps ti=<TaskInstance: COVID-19.insert_data manual__2023-11-22T19:29:07.263785+00:00 [queued]>
[2023-11-22T21:49:50.049+0000] {taskinstance.py:1159} INFO - Dependencies all met for dep_context=requeueable deps ti=<TaskInstance: COVID-19.insert_data manual__2023-11-22T19:29:07.263785+00:00 [queued]>
[2023-11-22T21:49:50.050+0000] {taskinstance.py:1361} INFO - Starting attempt 3 of 3
[2023-11-22T21:49:50.070+0000] {taskinstance.py:1382} INFO - Executing <Task(PythonOperator): insert_data> on 2023-11-22 19:29:07.263785+00:00
[2023-11-22T21:49:50.080+0000] {standard_task_runner.py:57} INFO - Started process 897 to run task
[2023-11-22T21:49:50.083+0000] {standard_task_runner.py:84} INFO - Running: ['***', 'tasks', 'run', 'COVID-19', 'insert_data', 'manual__2023-11-22T19:29:07.263785+00:00', '--job-id', '58', '--raw', '--subdir', 'DAGS_FOLDER/dag_etl.py', '--cfg-path', '/tmp/tmp7zpdg5iv']
[2023-11-22T21:49:50.086+0000] {standard_task_runner.py:85} INFO - Job 58: Subtask insert_data
[2023-11-22T21:49:50.144+0000] {task_command.py:416} INFO - Running <TaskInstance: COVID-19.insert_data manual__2023-11-22T19:29:07.263785+00:00 [running]> on host 6c2240d4b080
[2023-11-22T21:49:50.450+0000] {taskinstance.py:1662} INFO - Exporting env vars: AIRFLOW_CTX_DAG_OWNER='***' AIRFLOW_CTX_DAG_ID='COVID-19' AIRFLOW_CTX_TASK_ID='insert_data' AIRFLOW_CTX_EXECUTION_DATE='2023-11-22T19:29:07.263785+00:00' AIRFLOW_CTX_TRY_NUMBER='3' AIRFLOW_CTX_DAG_RUN_ID='manual__2023-11-22T19:29:07.263785+00:00'
[2023-11-22T21:49:50.463+0000] {base.py:73} INFO - Using connection ID 'postgres_connexion' for task execution.
[2023-11-22T21:49:50.480+0000] {taskinstance.py:1937} ERROR - Task failed with exception
Traceback (most recent call last):
  File "/home/airflow/.local/lib/python3.8/site-packages/airflow/operators/python.py", line 192, in execute
    return_value = self.execute_callable()
  File "/home/airflow/.local/lib/python3.8/site-packages/airflow/operators/python.py", line 209, in execute_callable
    return self.python_callable(*self.op_args, **self.op_kwargs)
  File "/opt/airflow/dags/dag_etl.py", line 63, in insert_data_into_db
    cursor.executemany(insert_departement_query, departement_data)
TypeError: 'ellipsis' object is not iterable
[2023-11-22T21:49:50.494+0000] {taskinstance.py:1400} INFO - Marking task as FAILED. dag_id=COVID-19, task_id=insert_data, execution_date=20231122T192907, start_date=20231122T214950, end_date=20231122T214950
[2023-11-22T21:49:50.512+0000] {standard_task_runner.py:104} ERROR - Failed to execute job 58 for task insert_data ('ellipsis' object is not iterable; 897)
[2023-11-22T21:49:50.539+0000] {local_task_job_runner.py:228} INFO - Task exited with return code 1
[2023-11-22T21:49:50.561+0000] {taskinstance.py:2778} INFO - 0 downstream tasks scheduled from follow-on schedule check
