[2023-11-22T21:50:09.283+0000] {taskinstance.py:1159} INFO - Dependencies all met for dep_context=non-requeueable deps ti=<TaskInstance: COVID-19.insert_data manual__2023-11-22T19:29:07.263785+00:00 [queued]>
[2023-11-22T21:50:09.296+0000] {taskinstance.py:1159} INFO - Dependencies all met for dep_context=requeueable deps ti=<TaskInstance: COVID-19.insert_data manual__2023-11-22T19:29:07.263785+00:00 [queued]>
[2023-11-22T21:50:09.298+0000] {taskinstance.py:1361} INFO - Starting attempt 4 of 4
[2023-11-22T21:50:09.317+0000] {taskinstance.py:1382} INFO - Executing <Task(PythonOperator): insert_data> on 2023-11-22 19:29:07.263785+00:00
[2023-11-22T21:50:09.324+0000] {standard_task_runner.py:57} INFO - Started process 908 to run task
[2023-11-22T21:50:09.327+0000] {standard_task_runner.py:84} INFO - Running: ['***', 'tasks', 'run', 'COVID-19', 'insert_data', 'manual__2023-11-22T19:29:07.263785+00:00', '--job-id', '59', '--raw', '--subdir', 'DAGS_FOLDER/dag_etl.py', '--cfg-path', '/tmp/tmp18433z4i']
[2023-11-22T21:50:09.330+0000] {standard_task_runner.py:85} INFO - Job 59: Subtask insert_data
[2023-11-22T21:50:09.387+0000] {task_command.py:416} INFO - Running <TaskInstance: COVID-19.insert_data manual__2023-11-22T19:29:07.263785+00:00 [running]> on host 6c2240d4b080
[2023-11-22T21:50:09.664+0000] {taskinstance.py:1662} INFO - Exporting env vars: AIRFLOW_CTX_DAG_OWNER='***' AIRFLOW_CTX_DAG_ID='COVID-19' AIRFLOW_CTX_TASK_ID='insert_data' AIRFLOW_CTX_EXECUTION_DATE='2023-11-22T19:29:07.263785+00:00' AIRFLOW_CTX_TRY_NUMBER='4' AIRFLOW_CTX_DAG_RUN_ID='manual__2023-11-22T19:29:07.263785+00:00'
[2023-11-22T21:50:09.678+0000] {base.py:73} INFO - Using connection ID 'postgres_connexion' for task execution.
[2023-11-22T21:50:09.694+0000] {taskinstance.py:1937} ERROR - Task failed with exception
Traceback (most recent call last):
  File "/home/airflow/.local/lib/python3.8/site-packages/airflow/operators/python.py", line 192, in execute
    return_value = self.execute_callable()
  File "/home/airflow/.local/lib/python3.8/site-packages/airflow/operators/python.py", line 209, in execute_callable
    return self.python_callable(*self.op_args, **self.op_kwargs)
  File "/opt/airflow/dags/dag_etl.py", line 63, in insert_data_into_db
    cursor.executemany(insert_departement_query, departement_data)
TypeError: 'ellipsis' object is not iterable
[2023-11-22T21:50:09.711+0000] {taskinstance.py:1400} INFO - Marking task as FAILED. dag_id=COVID-19, task_id=insert_data, execution_date=20231122T192907, start_date=20231122T215009, end_date=20231122T215009
[2023-11-22T21:50:09.726+0000] {standard_task_runner.py:104} ERROR - Failed to execute job 59 for task insert_data ('ellipsis' object is not iterable; 908)
[2023-11-22T21:50:09.743+0000] {local_task_job_runner.py:228} INFO - Task exited with return code 1
[2023-11-22T21:50:09.762+0000] {taskinstance.py:2778} INFO - 0 downstream tasks scheduled from follow-on schedule check
